Traceback (most recent call last):
  File "c:\users\andrea\anaconda3\lib\site-packages\jupyter_cache\executors\utils.py", line 56, in single_nb_execution
    record_timing=False,
  File "c:\users\andrea\anaconda3\lib\site-packages\nbclient\client.py", line 1112, in execute
    return NotebookClient(nb=nb, resources=resources, km=km, **kwargs).execute()
  File "c:\users\andrea\anaconda3\lib\site-packages\nbclient\util.py", line 74, in wrapped
    return just_run(coro(*args, **kwargs))
  File "c:\users\andrea\anaconda3\lib\site-packages\nbclient\util.py", line 53, in just_run
    return loop.run_until_complete(coro)
  File "c:\users\andrea\anaconda3\lib\asyncio\base_events.py", line 584, in run_until_complete
    return future.result()
  File "c:\users\andrea\anaconda3\lib\site-packages\nbclient\client.py", line 554, in async_execute
    cell, index, execution_count=self.code_cells_executed + 1
  File "c:\users\andrea\anaconda3\lib\site-packages\nbclient\client.py", line 857, in async_execute_cell
    self._check_raise_for_error(cell, exec_reply)
  File "c:\users\andrea\anaconda3\lib\site-packages\nbclient\client.py", line 760, in _check_raise_for_error
    raise CellExecutionError.from_cell_and_msg(cell, exec_reply_content)
nbclient.exceptions.CellExecutionError: An error occurred while executing the following cell:
------------------
# basic
import sys
import os

# common
import numpy as np
import pandas as pd
import xarray as xr
import matplotlib.pyplot as plt
from datetime import datetime, timedelta
import pickle

#lib
from lib.plots_base import basemap_ibtracs, basemap_var, basemap_scatter, axplot_basemap, basemap_scatter_both, plot_target_area,plot_predictor_grid
from lib.plots_tcs import get_storm_color, get_category, Plot_DWTs_tracks
from lib.plots_aux import data_to_discret, colors_dwt
from lib.extract_tcs import Extract_Rectangle, dwt_tcs_count
from lib.predictor_definition_building import *

import warnings
warnings.filterwarnings('ignore')
from IPython.display import Image
------------------

[1;31m---------------------------------------------------------------------------[0m
[1;31mModuleNotFoundError[0m                       Traceback (most recent call last)
[1;32m<ipython-input-1-9742772fecc0>[0m in [0;36m<module>[1;34m[0m
[0;32m     12[0m [1;33m[0m[0m
[0;32m     13[0m [1;31m#lib[0m[1;33m[0m[1;33m[0m[1;33m[0m[0m
[1;32m---> 14[1;33m [1;32mfrom[0m [0mlib[0m[1;33m.[0m[0mplots_base[0m [1;32mimport[0m [0mbasemap_ibtracs[0m[1;33m,[0m [0mbasemap_var[0m[1;33m,[0m [0mbasemap_scatter[0m[1;33m,[0m [0maxplot_basemap[0m[1;33m,[0m [0mbasemap_scatter_both[0m[1;33m,[0m [0mplot_target_area[0m[1;33m,[0m[0mplot_predictor_grid[0m[1;33m[0m[1;33m[0m[0m
[0m[0;32m     15[0m [1;32mfrom[0m [0mlib[0m[1;33m.[0m[0mplots_tcs[0m [1;32mimport[0m [0mget_storm_color[0m[1;33m,[0m [0mget_category[0m[1;33m,[0m [0mPlot_DWTs_tracks[0m[1;33m[0m[1;33m[0m[0m
[0;32m     16[0m [1;32mfrom[0m [0mlib[0m[1;33m.[0m[0mplots_aux[0m [1;32mimport[0m [0mdata_to_discret[0m[1;33m,[0m [0mcolors_dwt[0m[1;33m[0m[1;33m[0m[0m

[1;31mModuleNotFoundError[0m: No module named 'lib.plots_base'
ModuleNotFoundError: No module named 'lib.plots_base'

